<?xml version="1.0" encoding="UTF-8"?>
<!-- Generated by org.testng.reporters.JUnitReportReporter -->
<testsuite skipped="3" hostname="DESKTOP-48CJMGQ" name="TestNG_Annotations.RetryLogic_Class" tests="6" failures="0" timestamp="18 Feb 2018 01:17:39 GMT" time="0.042" errors="1">
  <testcase name="Test3" time="0.007" classname="TestNG_Annotations.RetryLogic_Class"/>
  <testcase name="Test1" time="0.003" classname="TestNG_Annotations.RetryLogic_Class">
    <error type="junit.framework.AssertionFailedError" message="expected:&lt;false&gt; but was:&lt;true&gt;">
      <![CDATA[junit.framework.AssertionFailedError: expected:<false> but was:<true>
	at junit.framework.Assert.fail(Assert.java:47)
	at junit.framework.Assert.failNotEquals(Assert.java:282)
	at junit.framework.Assert.assertEquals(Assert.java:64)
	at junit.framework.Assert.assertEquals(Assert.java:149)
	at junit.framework.Assert.assertEquals(Assert.java:155)
	at TestNG_Annotations.RetryLogic_Class.Test1(RetryLogic_Class.java:11)
	at sun.reflect.NativeMethodAccessorImpl.invoke0(Native Method)
	at sun.reflect.NativeMethodAccessorImpl.invoke(Unknown Source)
	at sun.reflect.DelegatingMethodAccessorImpl.invoke(Unknown Source)
	at java.lang.reflect.Method.invoke(Unknown Source)
	at org.testng.internal.MethodInvocationHelper.invokeMethod(MethodInvocationHelper.java:108)
	at org.testng.internal.Invoker.invokeMethod(Invoker.java:661)
	at org.testng.internal.Invoker.retryFailed(Invoker.java:1014)
	at org.testng.internal.Invoker.invokeTestMethods(Invoker.java:1215)
	at org.testng.internal.TestMethodWorker.invokeTestMethods(TestMethodWorker.java:126)
	at org.testng.internal.TestMethodWorker.run(TestMethodWorker.java:109)
	at org.testng.TestRunner.privateRun(TestRunner.java:744)
	at org.testng.TestRunner.run(TestRunner.java:602)
	at org.testng.SuiteRunner.runTest(SuiteRunner.java:380)
	at org.testng.SuiteRunner.runSequentially(SuiteRunner.java:375)
	at org.testng.SuiteRunner.privateRun(SuiteRunner.java:340)
	at org.testng.SuiteRunner.run(SuiteRunner.java:289)
	at org.testng.SuiteRunnerWorker.runSuite(SuiteRunnerWorker.java:52)
	at org.testng.SuiteRunnerWorker.run(SuiteRunnerWorker.java:86)
	at org.testng.TestNG.runSuitesSequentially(TestNG.java:1301)
	at org.testng.TestNG.runSuitesLocally(TestNG.java:1226)
	at org.testng.TestNG.runSuites(TestNG.java:1144)
	at org.testng.TestNG.run(TestNG.java:1115)
	at org.testng.remote.AbstractRemoteTestNG.run(AbstractRemoteTestNG.java:114)
	at org.testng.remote.RemoteTestNG.initAndRun(RemoteTestNG.java:251)
	at org.testng.remote.RemoteTestNG.main(RemoteTestNG.java:77)
]]>
    </error>
  </testcase> <!-- Test1 -->
  <testcase name="Test1" time="0.017" classname="TestNG_Annotations.RetryLogic_Class">
    <skipped/>
  </testcase> <!-- Test1 -->
  <testcase name="Test1" time="0.002" classname="TestNG_Annotations.RetryLogic_Class">
    <skipped/>
  </testcase> <!-- Test1 -->
  <testcase name="Test2" time="0.009" classname="TestNG_Annotations.RetryLogic_Class"/>
  <testcase name="Test1" time="0.004" classname="TestNG_Annotations.RetryLogic_Class">
    <skipped/>
  </testcase> <!-- Test1 -->
</testsuite> <!-- TestNG_Annotations.RetryLogic_Class -->
